<?xml version="1.0" ?>
<!-- =================================================================================== -->
<!-- |    This document was autogenerated by xacro from robot.urdf.xacro               | -->
<!-- |    EDITING THIS FILE BY HAND IS NOT RECOMMENDED                                 | -->
<!-- =================================================================================== -->
<robot name="arm">
  <joint name="wrist_2_end_effector" type="revolute">
    <origin rpy="0 0 0" xyz="0.061 0 0"/>
    <parent link="wrist_2_link"/>
    <child link="robotiq_85_base_link"/>
    <axis xyz="1 0 0"/>
    <limit effort="1000" lower="-3.14159265358979" upper="3.14159265358979" velocity="2.0"/>
  </joint>
  <link name="robotiq_85_base_link">
    <inertial>
      <origin rpy="0 0 0" xyz="0.00021987 -2.3546E-10 0.030163"/>
      <mass value="0.30915"/>
      <inertia ixx="0.00028972" ixy="-5.7879E-10" ixz="-1.8543E-06" iyy="0.00030737" iyz="1.682E-12" izz="0.00019914"/>
    </inertial>
    <visual>
      <origin rpy="0 0 0" xyz="0 0 0"/>
      <geometry>
        <mesh filename="package://robotic_manipulator_6_dof/meshes/robotiq_85_base_link_fine.STL"/>
      </geometry>
      <material name="">
        <color rgba="0.1 0.1 0.1 1"/>
      </material>
    </visual>
    <collision>
      <origin rpy="0 0 0" xyz="0 0 0"/>
      <geometry>
        <mesh filename="package://robotic_manipulator_6_dof/meshes/robotiq_85_base_link_coarse.STL"/>
      </geometry>
    </collision>
  </link>
  <link name="left_outer_knuckle">
    <inertial>
      <origin rpy="0 0 0" xyz="0.0178331863169983 3.68915177224286E-11 0.0021442477325704"/>
      <mass value="0.00684838849434396"/>
      <inertia ixx="2.66832029033166E-07" ixy="1.66142314639824E-15" ixz="1.45945633322873E-07" iyy="1.3889233257419E-06" iyz="2.82951161241588E-15" izz="1.26603336914415E-06"/>
    </inertial>
    <visual>
      <origin rpy="0 0 0" xyz="0 0 0"/>
      <geometry>
        <mesh filename="package://robotic_manipulator_6_dof/meshes/outer_knuckle_fine.STL"/>
      </geometry>
      <material name="">
        <color rgba="0.1 0.1 0.1 1"/>
      </material>
    </visual>
    <collision>
      <origin rpy="0 0 0" xyz="0 0 0"/>
      <geometry>
        <mesh filename="package://robotic_manipulator_6_dof/meshes/outer_knuckle_coarse.STL"/>
      </geometry>
    </collision>
  </link>
  <joint name="finger_joint" type="revolute">
    <origin rpy="0 0 0" xyz="0.0306011444260539 0 0.0627920162695395"/>
    <parent link="robotiq_85_base_link"/>
    <child link="left_outer_knuckle"/>
    <axis xyz="0 -1 0"/>
    <limit effort="1000" lower="0" upper="0.725" velocity="2.0"/>
  </joint>
  <link name="left_outer_finger">
    <inertial>
      <origin rpy="0 0 0" xyz="0.00131451599174296 2.88942057994543E-15 0.0215404163180413"/>
      <mass value="0.0273093985570947"/>
      <inertia ixx="8.51629628283022E-06" ixy="2.58174336207405E-19" ixz="3.83829504344079E-07" iyy="6.9133328065108E-06" iyz="-7.58589926143789E-19" izz="2.25006832221981E-06"/>
    </inertial>
    <visual>
      <origin rpy="0 0 0" xyz="0 0 0"/>
      <geometry>
        <mesh filename="package://robotic_manipulator_6_dof/meshes/outer_finger_fine.STL"/>
      </geometry>
      <material name="">
        <color rgba="0.1 0.1 0.1 1"/>
      </material>
    </visual>
    <collision>
      <origin rpy="0 0 0" xyz="0 0 0"/>
      <geometry>
        <mesh filename="package://robotic_manipulator_6_dof/meshes/outer_finger_coarse.STL"/>
      </geometry>
    </collision>
  </link>
  <joint name="left_outer_finger_joint" type="fixed">
    <origin rpy="0 0 0" xyz="0.0316910442266543 0 -0.00193396375724605"/>
    <parent link="left_outer_knuckle"/>
    <child link="left_outer_finger"/>
    <axis xyz="0 -1 0"/>
  </joint>
  <link name="left_inner_knuckle">
    <inertial>
      <origin rpy="0 0 0" xyz="0.017097546626628 -3.93808524389535E-10 0.0224918438201868"/>
      <mass value="0.0110930853895903"/>
      <inertia ixx="4.23392770691541E-06" ixy="5.748978936968E-15" ixz="1.78855677119788E-06" iyy="3.96548790524392E-06" iyz="1.05464666369669E-14" izz="3.24068002883007E-06"/>
    </inertial>
    <visual>
      <origin rpy="0 0 0" xyz="0 0 0"/>
      <geometry>
        <mesh filename="package://robotic_manipulator_6_dof/meshes/inner_knuckle_fine.STL"/>
      </geometry>
      <material name="">
        <color rgba="0.1 0.1 0.1 1"/>
      </material>
    </visual>
    <collision>
      <origin rpy="0 0 0" xyz="0 0 0"/>
      <geometry>
        <mesh filename="package://robotic_manipulator_6_dof/meshes/inner_knuckle_coarse.STL"/>
      </geometry>
    </collision>
  </link>
  <joint name="left_inner_knuckle_joint" type="revolute">
    <origin rpy="0 0 0" xyz="0.0127000000001501 0 0.0693074999999639"/>
    <parent link="robotiq_85_base_link"/>
    <child link="left_inner_knuckle"/>
    <axis xyz="0 -1 0"/>
    <limit effort="1000" lower="0" upper="0.8757" velocity="2.0"/>
    <mimic joint="finger_joint" multiplier="1" offset="0"/>
  </joint>
  <link name="left_inner_finger">
    <inertial>
      <origin rpy="0 0 0" xyz="0.0060275613594574 -6.29183141465421E-15 0.00669925693133241"/>
      <mass value="0.00724255346165745"/>
      <inertia ixx="1.47824274053603E-06" ixy="-3.94884463570303E-19" ixz="-3.45268847648622E-07" iyy="1.70064480838395E-06" iyz="3.5059838910097E-19" izz="4.77151336838364E-07"/>
    </inertial>
    <visual>
      <origin rpy="0 0 0" xyz="0 0 0"/>
      <geometry>
        <mesh filename="package://robotic_manipulator_6_dof/meshes/inner_finger_fine.STL"/>
      </geometry>
      <material name="">
        <color rgba="0.1 0.1 0.1 1"/>
      </material>
    </visual>
    <collision>
      <origin rpy="0 0 0" xyz="0 0 0"/>
      <geometry>
        <mesh filename="package://robotic_manipulator_6_dof/meshes/inner_finger_coarse.STL"/>
      </geometry>
    </collision>
  </link>
  <joint name="left_inner_finger_joint" type="revolute">
    <origin rpy="0 0 0" xyz="0.034585310861294 0 0.0454970193817975"/>
    <parent link="left_inner_knuckle"/>
    <child link="left_inner_finger"/>
    <axis xyz="0 -1 0"/>
    <limit effort="1000" lower="0" upper="0.8757" velocity="2.0"/>
    <mimic joint="finger_joint" multiplier="-1" offset="0"/>
  </joint>
  <link name="right_inner_knuckle">
    <inertial>
      <origin rpy="0 0 0" xyz="0.0168606186773776 3.93808471820465E-10 0.0226699950793434"/>
      <mass value="0.0110930853895903"/>
      <inertia ixx="4.27134775939882E-06" ixy="-8.53568456728898E-15" ixz="1.77774229944246E-06" iyy="3.96548790524392E-06" iyz="-8.45108024914164E-15" izz="3.20325997634666E-06"/>
    </inertial>
    <visual>
      <origin rpy="0 0 0" xyz="0 0 0"/>
      <geometry>
        <mesh filename="package://robotic_manipulator_6_dof/meshes/inner_knuckle_fine.STL"/>
      </geometry>
      <material name="">
        <color rgba="0.1 0.1 0.1 1"/>
      </material>
    </visual>
    <collision>
      <origin rpy="0 0 0" xyz="0 0 0"/>
      <geometry>
        <mesh filename="package://robotic_manipulator_6_dof/meshes/inner_knuckle_coarse.STL"/>
      </geometry>
    </collision>
  </link>
  <joint name="right_inner_knuckle_joint" type="revolute">
    <origin rpy="0 0 3.14159265358979" xyz="-0.0126999999998499 0 0.0693075000000361"/>
    <parent link="robotiq_85_base_link"/>
    <child link="right_inner_knuckle"/>
    <axis xyz="0 1 0"/>
    <limit effort="1000" lower="0" upper="0.8757" velocity="2.0"/>
    <mimic joint="finger_joint" multiplier="-1" offset="0"/>
  </joint>
  <link name="right_inner_finger">
    <inertial>
      <origin rpy="0 0 0" xyz="0.00602756228812038 -6.47284509480176E-15 0.00669925609578108"/>
      <mass value="0.00724255346165744"/>
      <inertia ixx="1.47824283625957E-06" ixy="-3.95952064019123E-19" ixz="-3.45268708875543E-07" iyy="1.70064480838394E-06" iyz="3.55286507960029E-19" izz="4.77151241114822E-07"/>
    </inertial>
    <visual>
      <origin rpy="0 0 0" xyz="0 0 0"/>
      <geometry>
        <mesh filename="package://robotic_manipulator_6_dof/meshes/inner_finger_fine.STL"/>
      </geometry>
      <material name="">
        <color rgba="0.1 0.1 0.1 1"/>
      </material>
    </visual>
    <collision>
      <origin rpy="0 0 0" xyz="0 0 0"/>
      <geometry>
        <mesh filename="package://robotic_manipulator_6_dof/meshes/inner_finger_coarse.STL"/>
      </geometry>
    </collision>
  </link>
  <joint name="right_inner_finger_joint" type="revolute">
    <origin rpy="0 0 0" xyz="0.0341060475457406 0 0.0458573878541688"/>
    <parent link="right_inner_knuckle"/>
    <child link="right_inner_finger"/>
    <axis xyz="0 1 0"/>
    <limit effort="1000" lower="0" upper="0.8757" velocity="2.0"/>
    <mimic joint="finger_joint" multiplier="1" offset="0"/>
  </joint>
  <link name="right_outer_knuckle">
    <inertial>
      <origin rpy="0 0 0" xyz="0.0178097074051638 3.60493211424024E-11 0.00233123458346721"/>
      <mass value="0.00684838849401352"/>
      <inertia ixx="2.70004361573169E-07" ixy="1.59579467624491E-15" ixz="1.56396493788199E-07" iyy="1.38892332558312E-06" iyz="2.82357800318817E-15" izz="1.26286103637978E-06"/>
    </inertial>
    <visual>
      <origin rpy="0 0 0" xyz="0 0 0"/>
      <geometry>
        <mesh filename="package://robotic_manipulator_6_dof/meshes/outer_knuckle_fine.STL"/>
      </geometry>
      <material name="">
        <color rgba="0.1 0.1 0.1 1"/>
      </material>
    </visual>
    <collision>
      <origin rpy="0 0 0" xyz="0 0 0"/>
      <geometry>
        <mesh filename="package://robotic_manipulator_6_dof/meshes/outer_knuckle_coarse.STL"/>
      </geometry>
    </collision>
  </link>
  <joint name="right_outer_knuckle_joint" type="revolute">
    <origin rpy="0 0 3.14159265358979" xyz="-0.0306011444258893 0 0.0627920162695395"/>
    <parent link="robotiq_85_base_link"/>
    <child link="right_outer_knuckle"/>
    <axis xyz="0 1 0"/>
    <limit effort="1000" lower="0" upper="0.8757" velocity="2.0"/>
    <mimic joint="finger_joint" multiplier="-1" offset="0"/>
  </joint>
  <link name="right_outer_finger">
    <inertial>
      <origin rpy="0 0 0" xyz="0.00108844269639009 -2.611488350845E-15 0.0215530225245502"/>
      <mass value="0.0273093985570947"/>
      <inertia ixx="8.52366028592721E-06" ixy="3.41683380899422E-19" ixz="3.18003675694284E-07" iyy="6.91333280651081E-06" iyz="7.37726682706417E-19" izz="2.24270431912283E-06"/>
    </inertial>
    <visual>
      <origin rpy="0 0 0" xyz="0 0 0"/>
      <geometry>
        <mesh filename="package://robotic_manipulator_6_dof/meshes/outer_finger_fine.STL"/>
      </geometry>
      <material name="">
        <color rgba="0.1 0.1 0.1 1"/>
      </material>
    </visual>
    <collision>
      <origin rpy="0 0 0" xyz="0 0 0"/>
      <geometry>
        <mesh filename="package://robotic_manipulator_6_dof/meshes/outer_finger_coarse.STL"/>
      </geometry>
    </collision>
  </link>
  <joint name="right_outer_finger_joint" type="fixed">
    <origin rpy="0 0 0" xyz="0.0317095909367246 0 -0.0016013564954687"/>
    <parent link="right_outer_knuckle"/>
    <child link="right_outer_finger"/>
    <axis xyz="0 1 0"/>
  </joint>
  <material name="grey">
    <color rgba="0.5 0.5 0.5 1"/>
  </material>
  <link name="base_link">
    <visual>
      <origin rpy="0 0 0" xyz="0 0 0"/>
      <geometry>
        <box size="0.25 0.25 0.01"/>
      </geometry>
      <material name="grey">
        <color rgba="0.5 0.5 0.5 1"/>
      </material>
    </visual>
    <collision>
      <origin rpy="0 0 0" xyz="0 0 0"/>
      <geometry>
        <box size="0.20 0.20 0.005"/>
      </geometry>
    </collision>
  </link>
  <joint name="base_base_1" type="revolute">
    <parent link="base_link"/>
    <child link="base_1"/>
    <origin rpy="0 0 0" xyz="0.0 0 0.005"/>
    <axis xyz="0 0 1"/>
    <limit effort="1000" lower="-3.14" upper="3.14" velocity="10"/>
  </joint>
  <link name="base_1">
    <visual>
      <origin rpy="0 0 0" xyz="0 0 0.075"/>
      <geometry>
        <cylinder length="0.15" radius="0.03"/>
      </geometry>
      <material name="grey"/>
    </visual>
    <collision>
      <origin rpy="0 0 0" xyz="0 0 0.075"/>
      <geometry>
        <cylinder length="0.10" radius="0.025"/>
      </geometry>
    </collision>
    <inertial>
      <origin rpy="0 0 0" xyz="0 0 0.075"/>
      <mass value="1.0"/>
      <inertia ixx="0.01" ixy="0" ixz="0" iyy="0.01" iyz="0" izz="0.01"/>
    </inertial>
  </link>
  <joint name="base_1_shoulder" type="revolute">
    <parent link="base_1"/>
    <child link="shoulder_link"/>
    <origin rpy="0 0 0" xyz="0.0 0 0.135"/>
    <axis xyz="1 0 0"/>
    <limit effort="1000" lower="-1.57" upper="1.57" velocity="10"/>
  </joint>
  <link name="shoulder_link">
    <visual>
      <origin rpy="0 0 0" xyz="0.063 0 0.160"/>
      <geometry>
        <cylinder length="0.35" radius="0.03"/>
      </geometry>
      <material name="grey"/>
    </visual>
    <collision>
      <origin rpy="0 0 0" xyz="0.063 0 0.160"/>
      <geometry>
        <cylinder length="0.30" radius="0.025"/>
      </geometry>
    </collision>
    <inertial>
      <origin rpy="0 0 0" xyz="0.063 0 0.160"/>
      <mass value="1.0"/>
      <inertia ixx="0.01" ixy="0" ixz="0" iyy="0.01" iyz="0" izz="0.01"/>
    </inertial>
  </link>
  <joint name="shoulder_upper_arm" type="revolute">
    <parent link="shoulder_link"/>
    <child link="upper_arm_link"/>
    <origin rpy="0 0 0" xyz="0.0 0 0.32"/>
    <axis xyz="1 0 0"/>
    <limit effort="1000" lower="-1.57" upper="1.57" velocity="10"/>
  </joint>
  <link name="upper_arm_link">
    <visual>
      <origin rpy="0 0 0" xyz="0.0 0 0.160"/>
      <geometry>
        <cylinder length="0.35" radius="0.03"/>
      </geometry>
      <material name="grey"/>
    </visual>
    <collision>
      <origin rpy="0 0 0" xyz="0.0 0 0.160"/>
      <geometry>
        <cylinder length="0.30" radius="0.025"/>
      </geometry>
    </collision>
    <inertial>
      <origin rpy="0 0 0" xyz="0.0 0 0.160"/>
      <mass value="1.0"/>
      <inertia ixx="0.01" ixy="0" ixz="0" iyy="0.01" iyz="0" izz="0.01"/>
    </inertial>
  </link>
  <joint name="upper_arm_forearm" type="revolute">
    <parent link="upper_arm_link"/>
    <child link="forearm_link"/>
    <origin rpy="0 0 0" xyz="0.0 0 0.305"/>
    <axis xyz="1 0 0"/>
    <limit effort="1000" lower="-1.57" upper="1.57" velocity="10"/>
  </joint>
  <link name="forearm_link">
    <visual>
      <origin rpy="0 1.57 0" xyz="0.068 0 0"/>
      <geometry>
        <cylinder length="0.07" radius="0.03"/>
      </geometry>
      <material name="grey"/>
    </visual>
    <collision>
      <origin rpy="0 1.57 0" xyz="0.068 0 0"/>
      <geometry>
        <cylinder length="0.06" radius="0.025"/>
      </geometry>
    </collision>
    <inertial>
      <origin rpy="0 1.57 0" xyz="0.068 0 0"/>
      <mass value="1.0"/>
      <inertia ixx="0.01" ixy="0" ixz="0" iyy="0.01" iyz="0" izz="0.01"/>
    </inertial>
  </link>
  <joint name="forearm_wrist_1" type="revolute">
    <parent link="forearm_link"/>
    <child link="wrist_1_link"/>
    <origin rpy="0 0 0" xyz="0.065 0 0.03"/>
    <axis xyz="0.0 0.0 1.0"/>
    <limit effort="1000" lower="-1.57" upper="1.57" velocity="10"/>
  </joint>
  <link name="wrist_1_link">
    <visual>
      <origin rpy="0 0 0" xyz="0.0 0 0.053"/>
      <geometry>
        <cylinder length="0.1" radius="0.03"/>
      </geometry>
      <material name="grey"/>
    </visual>
    <collision>
      <origin rpy="0 0 0" xyz="0.0 0 0.053"/>
      <geometry>
        <cylinder length="0.09" radius="0.025"/>
      </geometry>
    </collision>
    <inertial>
      <origin rpy="0 0 0" xyz="0.0 0 0.053"/>
      <mass value="1.0"/>
      <inertia ixx="0.01" ixy="0" ixz="0" iyy="0.01" iyz="0" izz="0.01"/>
    </inertial>
  </link>
  <joint name="wrist_1_wrist_2" type="revolute">
    <parent link="wrist_1_link"/>
    <child link="wrist_2_link"/>
    <origin rpy="0 0 0" xyz="0.03 0 0.073"/>
    <axis xyz="1 0 0"/>
    <limit effort="1000" lower="-1.57" upper="1.57" velocity="10"/>
  </joint>
  <link name="wrist_2_link">
    <visual>
      <origin rpy="0 1.57 0" xyz="0.028 0.0 0.0"/>
      <geometry>
        <cylinder length="0.05" radius="0.03"/>
      </geometry>
      <material name="grey"/>
    </visual>
    <collision>
      <origin rpy="0 1.57 0" xyz="0.028 0.0 0.0"/>
      <geometry>
        <cylinder length="0.04" radius="0.025"/>
      </geometry>
    </collision>
    <inertial>
      <origin rpy="0 1.57 0" xyz="0.028 0.0 0.0"/>
      <mass value="1.0"/>
      <inertia ixx="0.01" ixy="0" ixz="0" iyy="0.01" iyz="0" izz="0.01"/>
    </inertial>
  </link>
  <!-- <joint name="wrist_2_end_effector" type="fixed">
        <parent link="wrist_2_link"/>
        <child link="end_effector_link"/>
        <origin xyz="0.061 0 0" rpy="0 0 0"/>
    </joint>

    <link name="end_effector_link">
        <visual>
            <origin xyz="0 0 0" rpy="0 0 0" />
            <geometry>
                <box size="0.01 0.01 0.01"/>
            </geometry>
            <material name="grey"/>
        </visual>
        <collision>
            <origin xyz="0 0 0" rpy="0 0 0" />
            <geometry>
                <box size="0.005 0.005 0.005"/>
            </geometry>
        </collision>
        <inertial>
            <origin xyz="0 0 0" rpy="0 0 0"/>
            <mass value="0.1"/>
            <inertia ixx="0.0001" ixy="0" ixz="0" iyy="0.0001" iyz="0" izz="0.0001"/>
        </inertial>
    </link> -->
  <joint name="wrist_2_end_effector" type="revolute">
    <origin rpy="0 0 0" xyz="0.061 0 0"/>
    <parent link="wrist_2_link"/>
    <child link="robotiq_85_base_link"/>
    <axis xyz="1 0 0"/>
    <limit effort="1000" lower="-3.14159265358979" upper="3.14159265358979" velocity="2.0"/>
  </joint>
  <link name="robotiq_85_base_link">
    <inertial>
      <origin rpy="0 0 0" xyz="0.00021987 -2.3546E-10 0.030163"/>
      <mass value="0.30915"/>
      <inertia ixx="0.00028972" ixy="-5.7879E-10" ixz="-1.8543E-06" iyy="0.00030737" iyz="1.682E-12" izz="0.00019914"/>
    </inertial>
    <visual>
      <origin rpy="0 0 0" xyz="0 0 0"/>
      <geometry>
        <mesh filename="package://robotic_manipulator_6_dof/meshes/robotiq_85_base_link_fine.STL"/>
      </geometry>
      <material name="">
        <color rgba="0.1 0.1 0.1 1"/>
      </material>
    </visual>
    <collision>
      <origin rpy="0 0 0" xyz="0 0 0"/>
      <geometry>
        <mesh filename="package://robotic_manipulator_6_dof/meshes/robotiq_85_base_link_coarse.STL"/>
      </geometry>
    </collision>
  </link>
  <link name="left_outer_knuckle">
    <inertial>
      <origin rpy="0 0 0" xyz="0.0178331863169983 3.68915177224286E-11 0.0021442477325704"/>
      <mass value="0.00684838849434396"/>
      <inertia ixx="2.66832029033166E-07" ixy="1.66142314639824E-15" ixz="1.45945633322873E-07" iyy="1.3889233257419E-06" iyz="2.82951161241588E-15" izz="1.26603336914415E-06"/>
    </inertial>
    <visual>
      <origin rpy="0 0 0" xyz="0 0 0"/>
      <geometry>
        <mesh filename="package://robotic_manipulator_6_dof/meshes/outer_knuckle_fine.STL"/>
      </geometry>
      <material name="">
        <color rgba="0.1 0.1 0.1 1"/>
      </material>
    </visual>
    <collision>
      <origin rpy="0 0 0" xyz="0 0 0"/>
      <geometry>
        <mesh filename="package://robotic_manipulator_6_dof/meshes/outer_knuckle_coarse.STL"/>
      </geometry>
    </collision>
  </link>
  <joint name="finger_joint" type="revolute">
    <origin rpy="0 0 0" xyz="0.0306011444260539 0 0.0627920162695395"/>
    <parent link="robotiq_85_base_link"/>
    <child link="left_outer_knuckle"/>
    <axis xyz="0 -1 0"/>
    <limit effort="1000" lower="0" upper="0.725" velocity="2.0"/>
  </joint>
  <link name="left_outer_finger">
    <inertial>
      <origin rpy="0 0 0" xyz="0.00131451599174296 2.88942057994543E-15 0.0215404163180413"/>
      <mass value="0.0273093985570947"/>
      <inertia ixx="8.51629628283022E-06" ixy="2.58174336207405E-19" ixz="3.83829504344079E-07" iyy="6.9133328065108E-06" iyz="-7.58589926143789E-19" izz="2.25006832221981E-06"/>
    </inertial>
    <visual>
      <origin rpy="0 0 0" xyz="0 0 0"/>
      <geometry>
        <mesh filename="package://robotic_manipulator_6_dof/meshes/outer_finger_fine.STL"/>
      </geometry>
      <material name="">
        <color rgba="0.1 0.1 0.1 1"/>
      </material>
    </visual>
    <collision>
      <origin rpy="0 0 0" xyz="0 0 0"/>
      <geometry>
        <mesh filename="package://robotic_manipulator_6_dof/meshes/outer_finger_coarse.STL"/>
      </geometry>
    </collision>
  </link>
  <joint name="left_outer_finger_joint" type="fixed">
    <origin rpy="0 0 0" xyz="0.0316910442266543 0 -0.00193396375724605"/>
    <parent link="left_outer_knuckle"/>
    <child link="left_outer_finger"/>
    <axis xyz="0 -1 0"/>
  </joint>
  <link name="left_inner_knuckle">
    <inertial>
      <origin rpy="0 0 0" xyz="0.017097546626628 -3.93808524389535E-10 0.0224918438201868"/>
      <mass value="0.0110930853895903"/>
      <inertia ixx="4.23392770691541E-06" ixy="5.748978936968E-15" ixz="1.78855677119788E-06" iyy="3.96548790524392E-06" iyz="1.05464666369669E-14" izz="3.24068002883007E-06"/>
    </inertial>
    <visual>
      <origin rpy="0 0 0" xyz="0 0 0"/>
      <geometry>
        <mesh filename="package://robotic_manipulator_6_dof/meshes/inner_knuckle_fine.STL"/>
      </geometry>
      <material name="">
        <color rgba="0.1 0.1 0.1 1"/>
      </material>
    </visual>
    <collision>
      <origin rpy="0 0 0" xyz="0 0 0"/>
      <geometry>
        <mesh filename="package://robotic_manipulator_6_dof/meshes/inner_knuckle_coarse.STL"/>
      </geometry>
    </collision>
  </link>
  <joint name="left_inner_knuckle_joint" type="revolute">
    <origin rpy="0 0 0" xyz="0.0127000000001501 0 0.0693074999999639"/>
    <parent link="robotiq_85_base_link"/>
    <child link="left_inner_knuckle"/>
    <axis xyz="0 -1 0"/>
    <limit effort="1000" lower="0" upper="0.8757" velocity="2.0"/>
    <mimic joint="finger_joint" multiplier="1" offset="0"/>
  </joint>
  <link name="left_inner_finger">
    <inertial>
      <origin rpy="0 0 0" xyz="0.0060275613594574 -6.29183141465421E-15 0.00669925693133241"/>
      <mass value="0.00724255346165745"/>
      <inertia ixx="1.47824274053603E-06" ixy="-3.94884463570303E-19" ixz="-3.45268847648622E-07" iyy="1.70064480838395E-06" iyz="3.5059838910097E-19" izz="4.77151336838364E-07"/>
    </inertial>
    <visual>
      <origin rpy="0 0 0" xyz="0 0 0"/>
      <geometry>
        <mesh filename="package://robotic_manipulator_6_dof/meshes/inner_finger_fine.STL"/>
      </geometry>
      <material name="">
        <color rgba="0.1 0.1 0.1 1"/>
      </material>
    </visual>
    <collision>
      <origin rpy="0 0 0" xyz="0 0 0"/>
      <geometry>
        <mesh filename="package://robotic_manipulator_6_dof/meshes/inner_finger_coarse.STL"/>
      </geometry>
    </collision>
  </link>
  <joint name="left_inner_finger_joint" type="revolute">
    <origin rpy="0 0 0" xyz="0.034585310861294 0 0.0454970193817975"/>
    <parent link="left_inner_knuckle"/>
    <child link="left_inner_finger"/>
    <axis xyz="0 -1 0"/>
    <limit effort="1000" lower="0" upper="0.8757" velocity="2.0"/>
    <mimic joint="finger_joint" multiplier="-1" offset="0"/>
  </joint>
  <link name="right_inner_knuckle">
    <inertial>
      <origin rpy="0 0 0" xyz="0.0168606186773776 3.93808471820465E-10 0.0226699950793434"/>
      <mass value="0.0110930853895903"/>
      <inertia ixx="4.27134775939882E-06" ixy="-8.53568456728898E-15" ixz="1.77774229944246E-06" iyy="3.96548790524392E-06" iyz="-8.45108024914164E-15" izz="3.20325997634666E-06"/>
    </inertial>
    <visual>
      <origin rpy="0 0 0" xyz="0 0 0"/>
      <geometry>
        <mesh filename="package://robotic_manipulator_6_dof/meshes/inner_knuckle_fine.STL"/>
      </geometry>
      <material name="">
        <color rgba="0.1 0.1 0.1 1"/>
      </material>
    </visual>
    <collision>
      <origin rpy="0 0 0" xyz="0 0 0"/>
      <geometry>
        <mesh filename="package://robotic_manipulator_6_dof/meshes/inner_knuckle_coarse.STL"/>
      </geometry>
    </collision>
  </link>
  <joint name="right_inner_knuckle_joint" type="revolute">
    <origin rpy="0 0 3.14159265358979" xyz="-0.0126999999998499 0 0.0693075000000361"/>
    <parent link="robotiq_85_base_link"/>
    <child link="right_inner_knuckle"/>
    <axis xyz="0 1 0"/>
    <limit effort="1000" lower="0" upper="0.8757" velocity="2.0"/>
    <mimic joint="finger_joint" multiplier="-1" offset="0"/>
  </joint>
  <link name="right_inner_finger">
    <inertial>
      <origin rpy="0 0 0" xyz="0.00602756228812038 -6.47284509480176E-15 0.00669925609578108"/>
      <mass value="0.00724255346165744"/>
      <inertia ixx="1.47824283625957E-06" ixy="-3.95952064019123E-19" ixz="-3.45268708875543E-07" iyy="1.70064480838394E-06" iyz="3.55286507960029E-19" izz="4.77151241114822E-07"/>
    </inertial>
    <visual>
      <origin rpy="0 0 0" xyz="0 0 0"/>
      <geometry>
        <mesh filename="package://robotic_manipulator_6_dof/meshes/inner_finger_fine.STL"/>
      </geometry>
      <material name="">
        <color rgba="0.1 0.1 0.1 1"/>
      </material>
    </visual>
    <collision>
      <origin rpy="0 0 0" xyz="0 0 0"/>
      <geometry>
        <mesh filename="package://robotic_manipulator_6_dof/meshes/inner_finger_coarse.STL"/>
      </geometry>
    </collision>
  </link>
  <joint name="right_inner_finger_joint" type="revolute">
    <origin rpy="0 0 0" xyz="0.0341060475457406 0 0.0458573878541688"/>
    <parent link="right_inner_knuckle"/>
    <child link="right_inner_finger"/>
    <axis xyz="0 1 0"/>
    <limit effort="1000" lower="0" upper="0.8757" velocity="2.0"/>
    <mimic joint="finger_joint" multiplier="1" offset="0"/>
  </joint>
  <link name="right_outer_knuckle">
    <inertial>
      <origin rpy="0 0 0" xyz="0.0178097074051638 3.60493211424024E-11 0.00233123458346721"/>
      <mass value="0.00684838849401352"/>
      <inertia ixx="2.70004361573169E-07" ixy="1.59579467624491E-15" ixz="1.56396493788199E-07" iyy="1.38892332558312E-06" iyz="2.82357800318817E-15" izz="1.26286103637978E-06"/>
    </inertial>
    <visual>
      <origin rpy="0 0 0" xyz="0 0 0"/>
      <geometry>
        <mesh filename="package://robotic_manipulator_6_dof/meshes/outer_knuckle_fine.STL"/>
      </geometry>
      <material name="">
        <color rgba="0.1 0.1 0.1 1"/>
      </material>
    </visual>
    <collision>
      <origin rpy="0 0 0" xyz="0 0 0"/>
      <geometry>
        <mesh filename="package://robotic_manipulator_6_dof/meshes/outer_knuckle_coarse.STL"/>
      </geometry>
    </collision>
  </link>
  <joint name="right_outer_knuckle_joint" type="revolute">
    <origin rpy="0 0 3.14159265358979" xyz="-0.0306011444258893 0 0.0627920162695395"/>
    <parent link="robotiq_85_base_link"/>
    <child link="right_outer_knuckle"/>
    <axis xyz="0 1 0"/>
    <limit effort="1000" lower="0" upper="0.8757" velocity="2.0"/>
    <mimic joint="finger_joint" multiplier="-1" offset="0"/>
  </joint>
  <link name="right_outer_finger">
    <inertial>
      <origin rpy="0 0 0" xyz="0.00108844269639009 -2.611488350845E-15 0.0215530225245502"/>
      <mass value="0.0273093985570947"/>
      <inertia ixx="8.52366028592721E-06" ixy="3.41683380899422E-19" ixz="3.18003675694284E-07" iyy="6.91333280651081E-06" iyz="7.37726682706417E-19" izz="2.24270431912283E-06"/>
    </inertial>
    <visual>
      <origin rpy="0 0 0" xyz="0 0 0"/>
      <geometry>
        <mesh filename="package://robotic_manipulator_6_dof/meshes/outer_finger_fine.STL"/>
      </geometry>
      <material name="">
        <color rgba="0.1 0.1 0.1 1"/>
      </material>
    </visual>
    <collision>
      <origin rpy="0 0 0" xyz="0 0 0"/>
      <geometry>
        <mesh filename="package://robotic_manipulator_6_dof/meshes/outer_finger_coarse.STL"/>
      </geometry>
    </collision>
  </link>
  <joint name="right_outer_finger_joint" type="fixed">
    <origin rpy="0 0 0" xyz="0.0317095909367246 0 -0.0016013564954687"/>
    <parent link="right_outer_knuckle"/>
    <child link="right_outer_finger"/>
    <axis xyz="0 1 0"/>
  </joint>
  <ros2_control name="ArmHardware" type="system">
    <hardware>
      <plugin>fake_components/GenericSystem</plugin>
    </hardware>
    <joint name="base_base_1">
      <command_interface name="position"/>
      <state_interface name="position"/>
      <state_interface name="velocity"/>
    </joint>
    <joint name="base_1_shoulder">
      <command_interface name="position"/>
      <state_interface name="position"/>
      <state_interface name="velocity"/>
    </joint>
    <joint name="shoulder_upper_arm">
      <command_interface name="position"/>
      <state_interface name="position"/>
      <state_interface name="velocity"/>
    </joint>
    <joint name="upper_arm_forearm">
      <command_interface name="position"/>
      <state_interface name="position"/>
      <state_interface name="velocity"/>
    </joint>
    <joint name="forearm_wrist_1">
      <command_interface name="position"/>
      <state_interface name="position"/>
      <state_interface name="velocity"/>
    </joint>
    <joint name="wrist_1_wrist_2">
      <command_interface name="position"/>
      <state_interface name="position"/>
      <state_interface name="velocity"/>
    </joint>
  </ros2_control>
</robot>
