<?xml version="1.0" ?>
<!-- =================================================================================== -->
<!-- |    This document was autogenerated by xacro from robot.urdf.xacro               | -->
<!-- |    EDITING THIS FILE BY HAND IS NOT RECOMMENDED                                 | -->
<!-- =================================================================================== -->
<robot name="arm">
  <link name="base_link">
    <visual>
      <origin rpy="0 0 0" xyz="0 0 0"/>
      <geometry>
        <box size="0.5 0.5 0.01"/>
      </geometry>
      <material name="grey">
        <color rgba="0.5 0.5 0.5 1"/>
      </material>
    </visual>
    <collision>
      <origin rpy="0 0 0" xyz="0 0 0"/>
      <geometry>
        <box size="0.5 0.5 0.01"/>
      </geometry>
    </collision>
  </link>
  <joint name="base_base_1" type="revolute">
    <parent link="base_link"/>
    <child link="base_1"/>
    <origin rpy="0 0 0" xyz="0.0 0 0.005"/>
    <axis xyz="0 0 1"/>
    <limit effort="1000" lower="-3.14" upper="3.14" velocity="10"/>
  </joint>
  <link name="base_1">
    <visual>
      <origin rpy="0 0 0" xyz="0 0 0.075"/>
      <geometry>
        <cylinder length="0.15" radius="0.03"/>
      </geometry>
      <material name="grey">
        <color rgba="0.5 0.5 0.5 1"/>
      </material>
    </visual>
    <collision>
      <origin rpy="0 0 0" xyz="0 0 0.075"/>
      <geometry>
        <cylinder length="0.15" radius="0.03"/>
      </geometry>
    </collision>
    <inertial>
      <origin rpy="0 0 0" xyz="0 0 0.075"/>
      <mass value="1.0"/>
      <inertia ixx="0.01" ixy="0" ixz="0" iyy="0.01" iyz="0" izz="0.01"/>
    </inertial>
  </link>
  <joint name="base_1_shoulder" type="revolute">
    <parent link="base_1"/>
    <child link="shoulder_link"/>
    <origin rpy="0 0 0" xyz="0.0 0 0.135"/>
    <axis xyz="1 0 0"/>
    <limit effort="1000" lower="-1.57" upper="1.57" velocity="10"/>
  </joint>
  <link name="shoulder_link">
    <visual>
      <origin rpy="0 0 0" xyz="0.063 0 0.160"/>
      <geometry>
        <cylinder length="0.35" radius="0.03"/>
      </geometry>
    </visual>
    <collision>
      <origin rpy="0 0 0" xyz="0.063 0 0.160"/>
      <geometry>
        <cylinder length="0.35" radius="0.03"/>
      </geometry>
    </collision>
    <inertial>
      <origin rpy="0 0 0" xyz="0.063 0 0.160"/>
      <mass value="1.0"/>
      <inertia ixx="0.01" ixy="0" ixz="0" iyy="0.01" iyz="0" izz="0.01"/>
    </inertial>
  </link>
  <joint name="shoulder_upper_arm" type="revolute">
    <parent link="shoulder_link"/>
    <child link="upper_arm_link"/>
    <origin rpy="0 0 0" xyz="0.0 0 0.32"/>
    <axis xyz="1 0 0"/>
    <limit effort="1000" lower="-1.57" upper="1.57" velocity="10"/>
  </joint>
  <link name="upper_arm_link">
    <visual>
      <origin rpy="0 0 0" xyz="0.0 0 0.160"/>
      <geometry>
        <cylinder length="0.35" radius="0.03"/>
      </geometry>
      <material name="grey">
        <color rgba="0.5 0.5 0.5 1"/>
      </material>
    </visual>
    <collision>
      <origin rpy="0 0 0" xyz="0.0 0 0.160"/>
      <geometry>
        <cylinder length="0.35" radius="0.03"/>
      </geometry>
    </collision>
    <inertial>
      <origin rpy="0 0 0" xyz="0.0 0 0.160"/>
      <mass value="1.0"/>
      <inertia ixx="0.01" ixy="0" ixz="0" iyy="0.01" iyz="0" izz="0.01"/>
    </inertial>
  </link>
  <joint name="upper_arm_forearm" type="revolute">
    <parent link="upper_arm_link"/>
    <child link="forearm_link"/>
    <origin rpy="0 0 0" xyz="0.0 0 0.305"/>
    <axis xyz="1 0 0"/>
    <limit effort="1000" lower="-1.57" upper="1.57" velocity="10"/>
  </joint>
  <link name="forearm_link">
    <visual>
      <origin rpy="0 1.57 0" xyz="0.068 0 0"/>
      <geometry>
        <cylinder length="0.07" radius="0.03"/>
      </geometry>
    </visual>
    <collision>
      <origin rpy="0 1.57 0" xyz="0.068 0 0"/>
      <geometry>
        <cylinder length="0.07" radius="0.03"/>
      </geometry>
    </collision>
    <inertial>
      <origin rpy="0 1.57 0" xyz="0.068 0 0"/>
      <mass value="1.0"/>
      <inertia ixx="0.01" ixy="0" ixz="0" iyy="0.01" iyz="0" izz="0.01"/>
    </inertial>
  </link>
  <joint name="forearm_wrist_1" type="revolute">
    <parent link="forearm_link"/>
    <child link="wrist_1_link"/>
    <origin rpy="0 0 0" xyz="0.065 0 0.03"/>
    <axis xyz="0.0 0.0 1.0"/>
    <limit effort="1000" lower="-1.57" upper="1.57" velocity="10"/>
  </joint>
  <link name="wrist_1_link">
    <visual>
      <origin rpy="0 0 0" xyz="0.0 0 0.053"/>
      <geometry>
        <cylinder length="0.1" radius="0.03"/>
      </geometry>
    </visual>
    <collision>
      <origin rpy="0 0 0" xyz="0.0 0 0.053"/>
      <geometry>
        <cylinder length="0.1" radius="0.03"/>
      </geometry>
    </collision>
    <inertial>
      <origin rpy="0 0 0" xyz="0.0 0 0.053"/>
      <mass value="1.0"/>
      <inertia ixx="0.01" ixy="0" ixz="0" iyy="0.01" iyz="0" izz="0.01"/>
    </inertial>
  </link>
  <joint name="wrist_1_wrist_2" type="revolute">
    <parent link="wrist_1_link"/>
    <child link="wrist_2_link"/>
    <origin rpy="0 0 0" xyz="0.03 0 0.073"/>
    <axis xyz="1 0 0"/>
    <limit effort="1000" lower="-1.57" upper="1.57" velocity="10"/>
  </joint>
  <link name="wrist_2_link">
    <visual>
      <origin rpy="0 1.57 0" xyz="0.028 0.0 0.0"/>
      <geometry>
        <cylinder length="0.05" radius="0.03"/>
      </geometry>
    </visual>
    <collision>
      <origin rpy="0 1.57 0" xyz="0.028 0.0 0.0"/>
      <geometry>
        <cylinder length="0.05" radius="0.03"/>
      </geometry>
    </collision>
    <inertial>
      <origin rpy="0 1.57 0" xyz="0.028 0.0 0.0"/>
      <mass value="1.0"/>
      <inertia ixx="0.01" ixy="0" ixz="0" iyy="0.01" iyz="0" izz="0.01"/>
    </inertial>
  </link>
  <joint name="wrist_2_end_effector" type="fixed">
    <parent link="wrist_2_link"/>
    <child link="end_effector_link"/>
    <origin rpy="0 0 0" xyz="0.081 0 0"/>
  </joint>
  <link name="end_effector_link">
    <visual>
      <origin rpy="0 0 0" xyz="0 0 0"/>
      <geometry>
        <box size="0.05 0.01 0.01"/>
      </geometry>
    </visual>
    <collision>
      <origin rpy="0 0 0" xyz="0 0 0"/>
      <geometry>
        <box size="0.05 0.01 0.01"/>
      </geometry>
    </collision>
    <inertial>
      <origin rpy="0 0 0" xyz="0 0 0"/>
      <mass value="0.1"/>
      <inertia ixx="0.0001" ixy="0" ixz="0" iyy="0.0001" iyz="0" izz="0.0001"/>
    </inertial>
  </link>
</robot>
